Workbook
Name SlicerCache_Table_1_Col_1: #N/A
Name SlicerCache_Table_1_Col_2: #N/A
Name SlicerCache_Table_2_Col_1: #N/A
Name SlicerCache_Table_2_Col_2: #N/A
Name SlicerCache_Table_3_Col_1: #N/A
Name SlicerCache_Table_3_Col_2: #N/A
Name SlicerCache_Table_3_Col_4: #N/A

Sheet Performance Dashboard
A1: PLAYER PERFORMANCE AND RANKINGS
A23: PLAYER RANKINGS

Sheet VFM
A1: player_name | B1: player_role | C1: team | D1: season | E1: sold_price_cr | F1: rating(percentile) | G1: IPL_RANK | H1: valueformoney(rating out of 100) | I1: stars
A2: Deepak Nair | B2: Bowler | C2: Hyderabad Hawks | D2: 2022 | E2: 1.5 | F2: 100 | G2: 1 | H2: 66.67 | I2: 5 - Steal_Buy
A3: Priya Singh | B3: Bowler | C3: Kolkata Knights | D3: 2022 | E3: 1.2 | F3: 62 | G3: 3 | H3: 51.67 | I3: 5 - Steal_Buy
A4: Suresh Rao | B4: Bowler | C4: Chennai Tigers | D4: 2022 | E4: 1.8 | F4: 66 | G4: 2 | H4: 36.67 | I4: 5 - Steal_Buy
A5: Ankit Verma | B5: Batsman | C5: Kolkata Knights | D5: 2022 | E5: 2 | F5: 32.9 | G5: 6 | H5: 16.45 | I5: 5 - Steal_Buy
A6: Kiran Mehta | B6: Batsman | C6: Mumbai Lions | D6: 2022 | E6: 3.5 | F6: 57.1 | G6: 4 | H6: 16.31 | I6: 5 - Steal_Buy
A7: Chris Blake | B7: Batsman | C7: Delhi Dynamos | D7: 2022 | E7: 6.5 | F7: 100 | G7: 1 | H7: 15.38 | I7: 5 - Steal_Buy
A8: Tom Sullivan | B8: Batsman | C8: Rajasthan Riders | D8: 2022 | E8: 7 | F8: 82.9 | G8: 2 | H8: 11.84 | I8: 5 - Steal_Buy
A9: Luca Ferreira | B9: All-Rounder | C9: Delhi Dynamos | D9: 2022 | E9: 10 | F9: 64 | G9: 2 | H9: 6.4 | I9: 4 - Good_Buy
A10: Vikram Das | B10: Batsman | C10: Hyderabad Hawks | D10: 2022 | E10: 5.5 | F10: 34.3 | G10: 5 | H10: 6.24 | I10: 4 - Good_Buy
A11: Praveen Joshi | B11: Bowler | C11: Mumbai Lions | D11: 2022 | E11: 1 | F11: 6 | G11: 6 | H11: 6 | I11: 4 - Good_Buy
A12: Nathan Ford | B12: Bowler | C12: Punjab Royals | D12: 2022 | E12: 9 | F12: 52 | G12: 4 | H12: 5.78 | I12: 3 - Fair_Buy
A13: Raj Sharma | B13: Batsman | C13: Mumbai Lions | D13: 2022 | E13: 14 | F13: 74.3 | G13: 3 | H13: 5.31 | I13: 3 - Fair_Buy
... A41: Sanjay Kumar | B41: Batsman | C41: Chennai Tigers | D41: 2023 | E41: 4 | F41: 0 | G41: 8 | H41: 0 | I41: 1 - Poor Buy

Sheet 2022_Stats
A1: player_name | B1: player_role | C1: team | D1: season | E1: sold_price_cr | F1: rating(percentile) | G1: valueformoney(rating out of 100) | H1: IPL_RANK | I1: stars | J1: runs | K1: average | L1: strike_rate | M1: bdry_pct | N1: wickets | O1: economy | P1: wkt_per_match | Q1: dot_ball_pct
A2: Deepak Nair | B2: Bowler | C2: Hyderabad Hawks | D2: 2022 | E2: 1.5 | F2: 100 | G2: 66.67 | H2: 1 | I2: 5 - Steal_Buy | J2: {=xlookup(A2,Batting!A:A,Batting!E:E,"")} | K2: {=xlookup(A2,Batting!A:A,Batting!F:F,"")} | L2: {=xlookup(A2,Batting!A:A,Batting!G:G,"")} | M2: {=xlookup(A2,Batting!A:A,Batting!H:H,"")} | N2: {=xlookup(A2,Bowling!A:A,Bowling!F:F,"")} -> 26 | O2: {=xlookup(A2,Bowling!A:A,Bowling!G:G,"")} -> 5.09 | P2: {=xlookup(A2,Bowling!A:A,Bowling!H:H,"")} -> 1.86 | Q2: {=xlookup(A2,Bowling!A:A,Bowling!I:I,"")} -> 61.78
A3: Priya Singh | B3: Bowler | C3: Kolkata Knights | D3: 2022 | E3: 1.2 | F3: 62 | G3: 51.67 | H3: 3 | I3: 5 - Steal_Buy | J3: {=xlookup(A3,Batting!A:A,Batting!E:E,"")} | K3: {=xlookup(A3,Batting!A:A,Batting!F:F,"")} | L3: {=xlookup(A3,Batting!A:A,Batting!G:G,"")} | M3: {=xlookup(A3,Batting!A:A,Batting!H:H,"")} | N3: {=xlookup(A3,Bowling!A:A,Bowling!F:F,"")} -> 25 | O3: {=xlookup(A3,Bowling!A:A,Bowling!G:G,"")} -> 5.69 | P3: {=xlookup(A3,Bowling!A:A,Bowling!H:H,"")} -> 1.79 | Q3: {=xlookup(A3,Bowling!A:A,Bowling!I:I,"")} -> 60.34
A4: Suresh Rao | B4: Bowler | C4: Chennai Tigers | D4: 2022 | E4: 1.8 | F4: 66 | G4: 36.67 | H4: 2 | I4: 5 - Steal_Buy | J4: {=xlookup(A4,Batting!A:A,Batting!E:E,"")} | K4: {=xlookup(A4,Batting!A:A,Batting!F:F,"")} | L4: {=xlookup(A4,Batting!A:A,Batting!G:G,"")} | M4: {=xlookup(A4,Batting!A:A,Batting!H:H,"")} | N4: {=xlookup(A4,Bowling!A:A,Bowling!F:F,"")} -> 23 | O4: {=xlookup(A4,Bowling!A:A,Bowling!G:G,"")} -> 5.63 | P4: {=xlookup(A4,Bowling!A:A,Bowling!H:H,"")} -> 1.64 | Q4: {=xlookup(A4,Bowling!A:A,Bowling!I:I,"")} -> 59.52
A5: Ankit Verma | B5: Batsman | C5: Kolkata Knights | D5: 2022 | E5: 2 | F5: 32.9 | G5: 16.45 | H5: 6 | I5: 5 - Steal_Buy | J5: {=xlookup(A5,Batting!A:A,Batting!E:E,"")} -> 310 | K5: {=xlookup(A5,Batting!A:A,Batting!F:F,"")} -> 25.83 | L5: {=xlookup(A5,Batting!A:A,Batting!G:G,"")} -> 119.23 | M5: {=xlookup(A5,Batting!A:A,Batting!H:H,"")} -> 51.61 | N5: {=xlookup(A5,Bowling!A:A,Bowling!F:F,"")} | O5: {=xlookup(A5,Bowling!A:A,Bowling!G:G,"")} | P5: {=xlookup(A5,Bowling!A:A,Bowling!H:H,"")} | Q5: {=xlookup(A5,Bowling!A:A,Bowling!I:I,"")}
A6: Kiran Mehta | B6: Batsman | C6: Mumbai Lions | D6: 2022 | E6: 3.5 | F6: 57.1 | G6: 16.31 | H6: 4 | I6: 5 - Steal_Buy | J6: {=xlookup(A6,Batting!A:A,Batting!E:E,"")} -> 390 | K6: {=xlookup(A6,Batting!A:A,Batting!F:F,"")} -> 30 | L6: {=xlookup(A6,Batting!A:A,Batting!G:G,"")} -> 125.81 | M6: {=xlookup(A6,Batting!A:A,Batting!H:H,"")} -> 55.38 | N6: {=xlookup(A6,Bowling!A:A,Bowling!F:F,"")} | O6: {=xlookup(A6,Bowling!A:A,Bowling!G:G,"")} | P6: {=xlookup(A6,Bowling!A:A,Bowling!H:H,"")} | Q6: {=xlookup(A6,Bowling!A:A,Bowling!I:I,"")}
A7: Chris Blake | B7: Batsman | C7: Delhi Dynamos | D7: 2022 | E7: 6.5 | F7: 100 | G7: 15.38 | H7: 1 | I7: 5 - Steal_Buy | J7: {=xlookup(A7,Batting!A:A,Batting!E:E,"")} -> 520 | K7: {=xlookup(A7,Batting!A:A,Batting!F:F,"")} -> 43.33 | L7: {=xlookup(A7,Batting!A:A,Batting!G:G,"")} -> 157.58 | M7: {=xlookup(A7,Batting!A:A,Batting!H:H,"")} -> 76.92 | N7: {=xlookup(A7,Bowling!A:A,Bowling!F:F,"")} | O7: {=xlookup(A7,Bowling!A:A,Bowling!G:G,"")} | P7: {=xlookup(A7,Bowling!A:A,Bowling!H:H,"")} | Q7: {=xlookup(A7,Bowling!A:A,Bowling!I:I,"")}
A8: Tom Sullivan | B8: Batsman | C8: Rajasthan Riders | D8: 2022 | E8: 7 | F8: 82.9 | G8: 11.84 | H8: 2 | I8: 5 - Steal_Buy | J8: {=xlookup(A8,Batting!A:A,Batting!E:E,"")} -> 430 | K8: {=xlookup(A8,Batting!A:A,Batting!F:F,"")} -> 33.08 | L8: {=xlookup(A8,Batting!A:A,Batting!G:G,"")} -> 126.47 | M8: {=xlookup(A8,Batting!A:A,Batting!H:H,"")} -> 59.53 | N8: {=xlookup(A8,Bowling!A:A,Bowling!F:F,"")} | O8: {=xlookup(A8,Bowling!A:A,Bowling!G:G,"")} | P8: {=xlookup(A8,Bowling!A:A,Bowling!H:H,"")} | Q8: {=xlookup(A8,Bowling!A:A,Bowling!I:I,"")}
A9: Luca Ferreira | B9: All-Rounder | C9: Delhi Dynamos | D9: 2022 | E9: 10 | F9: 64 | G9: 6.4 | H9: 2 | I9: 4 - Good_Buy | J9: {=xlookup(A9,Batting!A:A,Batting!E:E,"")} -> 290 | K9: {=xlookup(A9,Batting!A:A,Batting!F:F,"")} -> 22.31 | L9: {=xlookup(A9,Batting!A:A,Batting!G:G,"")} -> 126.09 | M9: {=xlookup(A9,Batting!A:A,Batting!H:H,"")} -> 57.24 | N9: {=xlookup(A9,Bowling!A:A,Bowling!F:F,"")} -> 13 | O9: {=xlookup(A9,Bowling!A:A,Bowling!G:G,"")} -> 6.5 | P9: {=xlookup(A9,Bowling!A:A,Bowling!H:H,"")} -> 0.93 | Q9: {=xlookup(A9,Bowling!A:A,Bowling!I:I,"")} -> 42.67
A10: Vikram Das | B10: Batsman | C10: Hyderabad Hawks | D10: 2022 | E10: 5.5 | F10: 34.3 | G10: 6.24 | H10: 5 | I10: 4 - Good_Buy | J10: {=xlookup(A10,Batting!A:A,Batting!E:E,"")} -> 360 | K10: {=xlookup(A10,Batting!A:A,Batting!F:F,"")} -> 27.69 | L10: {=xlookup(A10,Batting!A:A,Batting!G:G,"")} -> 124.14 | M10: {=xlookup(A10,Batting!A:A,Batting!H:H,"")} -> 50 | N10: {=xlookup(A10,Bowling!A:A,Bowling!F:F,"")} | O10: {=xlookup(A10,Bowling!A:A,Bowling!G:G,"")} | P10: {=xlookup(A10,Bowling!A:A,Bowling!H:H,"")} | Q10: {=xlookup(A10,Bowling!A:A,Bowling!I:I,"")}
A11: Praveen Joshi | B11: Bowler | C11: Mumbai Lions | D11: 2022 | E11: 1 | F11: 6 | G11: 6 | H11: 6 | I11: 4 - Good_Buy | J11: {=xlookup(A11,Batting!A:A,Batting!E:E,"")} | K11: {=xlookup(A11,Batting!A:A,Batting!F:F,"")} | L11: {=xlookup(A11,Batting!A:A,Batting!G:G,"")} | M11: {=xlookup(A11,Batting!A:A,Batting!H:H,"")} | N11: {=xlookup(A11,Bowling!A:A,Bowling!F:F,"")} -> 17 | O11: {=xlookup(A11,Bowling!A:A,Bowling!G:G,"")} -> 6.25 | P11: {=xlookup(A11,Bowling!A:A,Bowling!H:H,"")} -> 1.21 | Q11: {=xlookup(A11,Bowling!A:A,Bowling!I:I,"")} -> 49.68
A12: Nathan Ford | B12: Bowler | C12: Punjab Royals | D12: 2022 | E12: 9 | F12: 52 | G12: 5.78 | H12: 4 | I12: 3 - Fair_Buy | J12: {=xlookup(A12,Batting!A:A,Batting!E:E,"")} | K12: {=xlookup(A12,Batting!A:A,Batting!F:F,"")} | L12: {=xlookup(A12,Batting!A:A,Batting!G:G,"")} | M12: {=xlookup(A12,Batting!A:A,Batting!H:H,"")} | N12: {=xlookup(A12,Bowling!A:A,Bowling!F:F,"")} -> 20 | O12: {=xlookup(A12,Bowling!A:A,Bowling!G:G,"")} -> 5.38 | P12: {=xlookup(A12,Bowling!A:A,Bowling!H:H,"")} -> 1.43 | Q12: {=xlookup(A12,Bowling!A:A,Bowling!I:I,"")} -> 56.09
A13: Raj Sharma | B13: Batsman | C13: Mumbai Lions | D13: 2022 | E13: 14 | F13: 74.3 | G13: 5.31 | H13: 3 | I13: 3 - Fair_Buy | J13: {=xlookup(A13,Batting!A:A,Batting!E:E,"")} -> 480 | K13: {=xlookup(A13,Batting!A:A,Batting!F:F,"")} -> 34.29 | L13: {=xlookup(A13,Batting!A:A,Batting!G:G,"")} -> 126.32 | M13: {=xlookup(A13,Batting!A:A,Batting!H:H,"")} -> 57.5 | N13: {=xlookup(A13,Bowling!A:A,Bowling!F:F,"")} | O13: {=xlookup(A13,Bowling!A:A,Bowling!G:G,"")} | P13: {=xlookup(A13,Bowling!A:A,Bowling!H:H,"")} | Q13: {=xlookup(A13,Bowling!A:A,Bowling!I:I,"")}
... A21: Sanjay Kumar | B21: Batsman | C21: Chennai Tigers | D21: 2022 | E21: 2.5 | F21: 0 | G21: 0 | H21: 8 | I21: 1 - Poor Buy | J21: {=xlookup(A21,Batting!A:A,Batting!E:E,"")} -> 280 | K21: {=xlookup(A21,Batting!A:A,Batting!F:F,"")} -> 23.33 | L21: {=xlookup(A21,Batting!A:A,Batting!G:G,"")} -> 116.67 | M21: {=xlookup(A21,Batting!A:A,Batting!H:H,"")} -> 48.57 | N21: {=xlookup(A21,Bowling!A:A,Bowling!F:F,"")} | O21: {=xlookup(A21,Bowling!A:A,Bowling!G:G,"")} | P21: {=xlookup(A21,Bowling!A:A,Bowling!H:H,"")} | Q21: {=xlookup(A21,Bowling!A:A,Bowling!I:I,"")}
J42: {=IFERROR(XLOOKUP(1, (Batting!$A$2:$A$29=A42)*(Batting!$D$2:$D$29=D42), Batting!$E$2:$E$29),"")}
J43: {=IFERROR(XLOOKUP(1, (Batting!$A$2:$A$29=A43)*(Batting!$D$2:$D$29=D43), Batting!$E$2:$E$29),"")}
J44: {=IFERROR(XLOOKUP(1, (Batting!$A$2:$A$29=A44)*(Batting!$D$2:$D$29=D44), Batting!$E$2:$E$29),"")}
J45: {=IFERROR(XLOOKUP(1, (Batting!$A$2:$A$29=A45)*(Batting!$D$2:$D$29=D45), Batting!$E$2:$E$29),"")}
J46: {=IFERROR(XLOOKUP(1, (Batting!$A$2:$A$29=A46)*(Batting!$D$2:$D$29=D46), Batting!$E$2:$E$29),"")}
J47: {=IFERROR(XLOOKUP(1, (Batting!$A$2:$A$29=A47)*(Batting!$D$2:$D$29=D47), Batting!$E$2:$E$29),"")}
J48: {=IFERROR(XLOOKUP(1, (Batting!$A$2:$A$29=A48)*(Batting!$D$2:$D$29=D48), Batting!$E$2:$E$29),"")}
J49: {=IFERROR(XLOOKUP(1, (Batting!$A$2:$A$29=A49)*(Batting!$D$2:$D$29=D49), Batting!$E$2:$E$29),"")}
J50: {=IFERROR(XLOOKUP(1, (Batting!$A$2:$A$29=A50)*(Batting!$D$2:$D$29=D50), Batting!$E$2:$E$29),"")}
J51: {=IFERROR(XLOOKUP(1, (Batting!$A$2:$A$29=A51)*(Batting!$D$2:$D$29=D51), Batting!$E$2:$E$29),"")}
J52: {=IFERROR(XLOOKUP(1, (Batting!$A$2:$A$29=A52)*(Batting!$D$2:$D$29=D52), Batting!$E$2:$E$29),"")}
J53: {=IFERROR(XLOOKUP(1, (Batting!$A$2:$A$29=A53)*(Batting!$D$2:$D$29=D53), Batting!$E$2:$E$29),"")}
J54: {=IFERROR(XLOOKUP(1, (Batting!$A$2:$A$29=A54)*(Batting!$D$2:$D$29=D54), Batting!$E$2:$E$29),"")}

Sheet 2022_Pivot

Sheet 2023_Stats
A1: player_name | B1: player_role | C1: team | D1: season | E1: sold_price_cr | F1: rating(percentile) | G1: valueformoney(rating out of 100) | H1: IPL_RANK | I1: stars | J1: runs | K1: average | L1: strike_rate | M1: bdry_pct | N1: wickets | O1: economy | P1: wkt_per_match | Q1: dot_ball_pct
A2: Deepak Nair | B2: Bowler | C2: Hyderabad Hawks | D2: 2023 | E2: 1.8 | F2: 100 | G2: 55.56 | H2: 1 | I2: 5 - Steal_Buy | J2: {=xlookup(A2,Batting!A:A,Batting!E:E,"")} | K2: {=xlookup(A2,Batting!A:A,Batting!F:F,"")} | L2: {=xlookup(A2,Batting!A:A,Batting!G:G,"")} | M2: {=xlookup(A2,Batting!A:A,Batting!H:H,"")} | N2: {=xlookup(A2,Bowling!A:A,Bowling!F:F,"")} -> 26 | O2: {=xlookup(A2,Bowling!A:A,Bowling!G:G,"")} -> 5.09 | P2: {=xlookup(A2,Bowling!A:A,Bowling!H:H,"")} -> 1.86 | Q2: {=xlookup(A2,Bowling!A:A,Bowling!I:I,"")} -> 61.78
A3: Priya Singh | B3: Bowler | C3: Kolkata Knights | D3: 2023 | E3: 2 | F3: 68 | G3: 34 | H3: 2 | I3: 5 - Steal_Buy | J3: {=xlookup(A3,Batting!A:A,Batting!E:E,"")} | K3: {=xlookup(A3,Batting!A:A,Batting!F:F,"")} | L3: {=xlookup(A3,Batting!A:A,Batting!G:G,"")} | M3: {=xlookup(A3,Batting!A:A,Batting!H:H,"")} | N3: {=xlookup(A3,Bowling!A:A,Bowling!F:F,"")} -> 25 | O3: {=xlookup(A3,Bowling!A:A,Bowling!G:G,"")} -> 5.69 | P3: {=xlookup(A3,Bowling!A:A,Bowling!H:H,"")} -> 1.79 | Q3: {=xlookup(A3,Bowling!A:A,Bowling!I:I,"")} -> 60.34
A4: Suresh Rao | B4: Bowler | C4: Chennai Tigers | D4: 2023 | E4: 2.5 | F4: 60 | G4: 24 | H4: 3 | I4: 5 - Steal_Buy | J4: {=xlookup(A4,Batting!A:A,Batting!E:E,"")} | K4: {=xlookup(A4,Batting!A:A,Batting!F:F,"")} | L4: {=xlookup(A4,Batting!A:A,Batting!G:G,"")} | M4: {=xlookup(A4,Batting!A:A,Batting!H:H,"")} | N4: {=xlookup(A4,Bowling!A:A,Bowling!F:F,"")} -> 23 | O4: {=xlookup(A4,Bowling!A:A,Bowling!G:G,"")} -> 5.63 | P4: {=xlookup(A4,Bowling!A:A,Bowling!H:H,"")} -> 1.64 | Q4: {=xlookup(A4,Bowling!A:A,Bowling!I:I,"")} -> 59.52
A5: Kiran Mehta | B5: Batsman | C5: Mumbai Lions | D5: 2023 | E5: 4 | F5: 50 | G5: 12.5 | H5: 4 | I5: 5 - Steal_Buy | J5: {=xlookup(A5,Batting!A:A,Batting!E:E,"")} -> 390 | K5: {=xlookup(A5,Batting!A:A,Batting!F:F,"")} -> 30 | L5: {=xlookup(A5,Batting!A:A,Batting!G:G,"")} -> 125.81 | M5: {=xlookup(A5,Batting!A:A,Batting!H:H,"")} -> 55.38 | N5: {=xlookup(A5,Bowling!A:A,Bowling!F:F,"")} | O5: {=xlookup(A5,Bowling!A:A,Bowling!G:G,"")} | P5: {=xlookup(A5,Bowling!A:A,Bowling!H:H,"")} | Q5: {=xlookup(A5,Bowling!A:A,Bowling!I:I,"")}
A6: Chris Blake | B6: Batsman | C6: Delhi Dynamos | D6: 2023 | E6: 9 | F6: 100 | G6: 11.11 | H6: 1 | I6: 5 - Steal_Buy | J6: {=xlookup(A6,Batting!A:A,Batting!E:E,"")} -> 520 | K6: {=xlookup(A6,Batting!A:A,Batting!F:F,"")} -> 43.33 | L6: {=xlookup(A6,Batting!A:A,Batting!G:G,"")} -> 157.58 | M6: {=xlookup(A6,Batting!A:A,Batting!H:H,"")} -> 76.92 | N6: {=xlookup(A6,Bowling!A:A,Bowling!F:F,"")} | O6: {=xlookup(A6,Bowling!A:A,Bowling!G:G,"")} | P6: {=xlookup(A6,Bowling!A:A,Bowling!H:H,"")} | Q6: {=xlookup(A6,Bowling!A:A,Bowling!I:I,"")}
A7: Tom Sullivan | B7: Batsman | C7: Rajasthan Riders | D7: 2023 | E7: 8 | F7: 82.9 | G7: 10.36 | H7: 2 | I7: 5 - Steal_Buy | J7: {=xlookup(A7,Batting!A:A,Batting!E:E,"")} -> 430 | K7: {=xlookup(A7,Batting!A:A,Batting!F:F,"")} -> 33.08 | L7: {=xlookup(A7,Batting!A:A,Batting!G:G,"")} -> 126.47 | M7: {=xlookup(A7,Batting!A:A,Batting!H:H,"")} -> 59.53 | N7: {=xlookup(A7,Bowling!A:A,Bowling!F:F,"")} | O7: {=xlookup(A7,Bowling!A:A,Bowling!G:G,"")} | P7: {=xlookup(A7,Bowling!A:A,Bowling!H:H,"")} | Q7: {=xlookup(A7,Bowling!A:A,Bowling!I:I,"")}
A8: Ankit Verma | B8: Batsman | C8: Kolkata Knights | D8: 2023 | E8: 3.5 | F8: 28.6 | G8: 8.17 | H8: 6 | I8: 5 - Steal_Buy | J8: {=xlookup(A8,Batting!A:A,Batting!E:E,"")} -> 310 | K8: {=xlookup(A8,Batting!A:A,Batting!F:F,"")} -> 25.83 | L8: {=xlookup(A8,Batting!A:A,Batting!G:G,"")} -> 119.23 | M8: {=xlookup(A8,Batting!A:A,Batting!H:H,"")} -> 51.61 | N8: {=xlookup(A8,Bowling!A:A,Bowling!F:F,"")} | O8: {=xlookup(A8,Bowling!A:A,Bowling!G:G,"")} | P8: {=xlookup(A8,Bowling!A:A,Bowling!H:H,"")} | Q8: {=xlookup(A8,Bowling!A:A,Bowling!I:I,"")}
A9: Vikram Das | B9: Batsman | C9: Hyderabad Hawks | D9: 2023 | E9: 6 | F9: 41.4 | G9: 6.9 | H9: 5 | I9: 4 - Good_Buy | J9: {=xlookup(A9,Batting!A:A,Batting!E:E,"")} -> 360 | K9: {=xlookup(A9,Batting!A:A,Batting!F:F,"")} -> 27.69 | L9: {=xlookup(A9,Batting!A:A,Batting!G:G,"")} -> 124.14 | M9: {=xlookup(A9,Batting!A:A,Batting!H:H,"")} -> 50 | N9: {=xlookup(A9,Bowling!A:A,Bowling!F:F,"")} | O9: {=xlookup(A9,Bowling!A:A,Bowling!G:G,"")} | P9: {=xlookup(A9,Bowling!A:A,Bowling!H:H,"")} | Q9: {=xlookup(A9,Bowling!A:A,Bowling!I:I,"")}
A10: Hamid Shaikh | B10: Batsman | C10: Delhi Dynamos | D10: 2023 | E10: 3.5 | F10: 22.9 | G10: 6.54 | H10: 7 | I10: 4 - Good_Buy | J10: {=xlookup(A10,Batting!A:A,Batting!E:E,"")} -> 300 | K10: {=xlookup(A10,Batting!A:A,Batting!F:F,"")} -> 25 | L10: {=xlookup(A10,Batting!A:A,Batting!G:G,"")} -> 117.65 | M10: {=xlookup(A10,Batting!A:A,Batting!H:H,"")} -> 50 | N10: {=xlookup(A10,Bowling!A:A,Bowling!F:F,"")} | O10: {=xlookup(A10,Bowling!A:A,Bowling!G:G,"")} | P10: {=xlookup(A10,Bowling!A:A,Bowling!H:H,"")} | Q10: {=xlookup(A10,Bowling!A:A,Bowling!I:I,"")}
A11: Nathan Ford | B11: Bowler | C11: Punjab Royals | D11: 2023 | E11: 7.5 | F11: 44 | G11: 5.87 | H11: 4 | I11: 3 - Fair_Buy | J11: {=xlookup(A11,Batting!A:A,Batting!E:E,"")} | K11: {=xlookup(A11,Batting!A:A,Batting!F:F,"")} | L11: {=xlookup(A11,Batting!A:A,Batting!G:G,"")} | M11: {=xlookup(A11,Batting!A:A,Batting!H:H,"")} | N11: {=xlookup(A11,Bowling!A:A,Bowling!F:F,"")} -> 20 | O11: {=xlookup(A11,Bowling!A:A,Bowling!G:G,"")} -> 5.38 | P11: {=xlookup(A11,Bowling!A:A,Bowling!H:H,"")} -> 1.43 | Q11: {=xlookup(A11,Bowling!A:A,Bowling!I:I,"")} -> 56.09
A12: Praveen Joshi | B12: Bowler | C12: Mumbai Lions | D12: 2023 | E12: 1.2 | F12: 6 | G12: 5 | H12: 6 | I12: 3 - Fair_Buy | J12: {=xlookup(A12,Batting!A:A,Batting!E:E,"")} | K12: {=xlookup(A12,Batting!A:A,Batting!F:F,"")} | L12: {=xlookup(A12,Batting!A:A,Batting!G:G,"")} | M12: {=xlookup(A12,Batting!A:A,Batting!H:H,"")} | N12: {=xlookup(A12,Bowling!A:A,Bowling!F:F,"")} -> 17 | O12: {=xlookup(A12,Bowling!A:A,Bowling!G:G,"")} -> 6.25 | P12: {=xlookup(A12,Bowling!A:A,Bowling!H:H,"")} -> 1.21 | Q12: {=xlookup(A12,Bowling!A:A,Bowling!I:I,"")} -> 49.68
A13: Luca Ferreira | B13: All-Rounder | C13: Delhi Dynamos | D13: 2023 | E13: 12 | F13: 60 | G13: 5 | H13: 3 | I13: 3 - Fair_Buy | J13: {=xlookup(A13,Batting!A:A,Batting!E:E,"")} -> 290 | K13: {=xlookup(A13,Batting!A:A,Batting!F:F,"")} -> 22.31 | L13: {=xlookup(A13,Batting!A:A,Batting!G:G,"")} -> 126.09 | M13: {=xlookup(A13,Batting!A:A,Batting!H:H,"")} -> 57.24 | N13: {=xlookup(A13,Bowling!A:A,Bowling!F:F,"")} -> 13 | O13: {=xlookup(A13,Bowling!A:A,Bowling!G:G,"")} -> 6.5 | P13: {=xlookup(A13,Bowling!A:A,Bowling!H:H,"")} -> 0.93 | Q13: {=xlookup(A13,Bowling!A:A,Bowling!I:I,"")} -> 42.67
... A21: Sanjay Kumar | B21: Batsman | C21: Chennai Tigers | D21: 2023 | E21: 4 | F21: 0 | G21: 0 | H21: 8 | I21: 1 - Poor Buy | J21: {=xlookup(A21,Batting!A:A,Batting!E:E,"")} -> 280 | K21: {=xlookup(A21,Batting!A:A,Batting!F:F,"")} -> 23.33 | L21: {=xlookup(A21,Batting!A:A,Batting!G:G,"")} -> 116.67 | M21: {=xlookup(A21,Batting!A:A,Batting!H:H,"")} -> 48.57 | N21: {=xlookup(A21,Bowling!A:A,Bowling!F:F,"")} | O21: {=xlookup(A21,Bowling!A:A,Bowling!G:G,"")} | P21: {=xlookup(A21,Bowling!A:A,Bowling!H:H,"")} | Q21: {=xlookup(A21,Bowling!A:A,Bowling!I:I,"")}

Sheet 2023_pivot

Sheet Dashboard
A1: PLAYER PERFORMANCE DASHBOARD

Sheet All_Stats
A1: {={'2022_Stats'!A1:Q21; '2023_Stats'!A2:Q21}} -> player_name | B1: player_role | C1: team | D1: season | E1: sold_price_cr | F1: rating(percentile) | G1: valueformoney(rating out of 100) | H1: IPL_RANK | I1: stars | J1: runs | K1: average | L1: strike_rate | M1: bdry_pct | N1: wickets | O1: economy | P1: wkt_per_match | Q1: dot_ball_pct
A2: Deepak Nair | B2: Bowler | C2: Hyderabad Hawks | D2: 2022 | E2: 1.5 | F2: 100 | G2: 66.67 | H2: 1 | I2: 5 - Steal_Buy | N2: 26 | O2: 5.09 | P2: 1.86 | Q2: 61.78
A3: Priya Singh | B3: Bowler | C3: Kolkata Knights | D3: 2022 | E3: 1.2 | F3: 62 | G3: 51.67 | H3: 3 | I3: 5 - Steal_Buy | N3: 25 | O3: 5.69 | P3: 1.79 | Q3: 60.34
A4: Suresh Rao | B4: Bowler | C4: Chennai Tigers | D4: 2022 | E4: 1.8 | F4: 66 | G4: 36.67 | H4: 2 | I4: 5 - Steal_Buy | N4: 23 | O4: 5.63 | P4: 1.64 | Q4: 59.52
A5: Ankit Verma | B5: Batsman | C5: Kolkata Knights | D5: 2022 | E5: 2 | F5: 32.9 | G5: 16.45 | H5: 6 | I5: 5 - Steal_Buy | J5: 310 | K5: 25.83 | L5: 119.23 | M5: 51.61
A6: Kiran Mehta | B6: Batsman | C6: Mumbai Lions | D6: 2022 | E6: 3.5 | F6: 57.1 | G6: 16.31 | H6: 4 | I6: 5 - Steal_Buy | J6: 390 | K6: 30 | L6: 125.81 | M6: 55.38
A7: Chris Blake | B7: Batsman | C7: Delhi Dynamos | D7: 2022 | E7: 6.5 | F7: 100 | G7: 15.38 | H7: 1 | I7: 5 - Steal_Buy | J7: 520 | K7: 43.33 | L7: 157.58 | M7: 76.92
A8: Tom Sullivan | B8: Batsman | C8: Rajasthan Riders | D8: 2022 | E8: 7 | F8: 82.9 | G8: 11.84 | H8: 2 | I8: 5 - Steal_Buy | J8: 430 | K8: 33.08 | L8: 126.47 | M8: 59.53
A9: Luca Ferreira | B9: All-Rounder | C9: Delhi Dynamos | D9: 2022 | E9: 10 | F9: 64 | G9: 6.4 | H9: 2 | I9: 4 - Good_Buy | J9: 290 | K9: 22.31 | L9: 126.09 | M9: 57.24 | N9: 13 | O9: 6.5 | P9: 0.93 | Q9: 42.67
A10: Vikram Das | B10: Batsman | C10: Hyderabad Hawks | D10: 2022 | E10: 5.5 | F10: 34.3 | G10: 6.24 | H10: 5 | I10: 4 - Good_Buy | J10: 360 | K10: 27.69 | L10: 124.14 | M10: 50
A11: Praveen Joshi | B11: Bowler | C11: Mumbai Lions | D11: 2022 | E11: 1 | F11: 6 | G11: 6 | H11: 6 | I11: 4 - Good_Buy | N11: 17 | O11: 6.25 | P11: 1.21 | Q11: 49.68
A12: Nathan Ford | B12: Bowler | C12: Punjab Royals | D12: 2022 | E12: 9 | F12: 52 | G12: 5.78 | H12: 4 | I12: 3 - Fair_Buy | N12: 20 | O12: 5.38 | P12: 1.43 | Q12: 56.09
A13: Raj Sharma | B13: Batsman | C13: Mumbai Lions | D13: 2022 | E13: 14 | F13: 74.3 | G13: 5.31 | H13: 3 | I13: 3 - Fair_Buy | J13: 480 | K13: 34.29 | L13: 126.32 | M13: 57.5
A14: Arjun Patel | B14: All-Rounder | C14: Chennai Tigers | D14: 2022 | E14: 15.25 | F14: 75 | G14: 4.92 | H14: 1 | I14: 3 - Fair_Buy | J14: 310 | K14: 22.14 | L14: 129.17 | M14: 63.23 | N14: 14 | O14: 6.73 | P14: 1 | Q14: 43.27
A15: Hamid Shaikh | B15: Batsman | C15: Delhi Dynamos | D15: 2022 | E15: 3 | F15: 14.3 | G15: 4.77 | H15: 7 | I15: 3 - Fair_Buy | J15: 300 | K15: 25 | L15: 117.65 | M15: 50
A16: James Tanner | B16: All-Rounder | C16: Rajasthan Riders | D16: 2022 | E16: 11 | F16: 49 | G16: 4.45 | H16: 3 | I16: 3 - Fair_Buy | J16: 280 | K16: 20 | L16: 127.27 | M16: 55.71 | N16: 12 | O16: 6.46 | P16: 0.86 | Q16: 43.4
A17: Carlos Mendez | B17: All-Rounder | C17: Punjab Royals | D17: 2022 | E17: 8.5 | F17: 34 | G17: 4 | H17: 4 | I17: 3 - Fair_Buy | J17: 260 | K17: 20 | L17: 123.81 | M17: 56.92 | N17: 11 | O17: 6.41 | P17: 0.79 | Q17: 42.75
A18: Rohan Gill | B18: All-Rounder | C18: Mumbai Lions | D18: 2022 | E18: 8 | F18: 29 | G18: 3.62 | H18: 5 | I18: 2 - Overpriced | J18: 240 | K18: 17.14 | L18: 120 | M18: 55.83 | N18: 11 | O18: 6.2 | P18: 0.79 | Q18: 40.58
A19: Brendon Chase | B19: Bowler | C19: Punjab Royals | D19: 2022 | E19: 4.5 | F19: 14 | G19: 3.11 | H19: 5 | I19: 2 - Overpriced | N19: 21 | O19: 5.92 | P19: 1.5 | Q19: 48.61
A20: Marco de Bruyn | B20: All-Rounder | C20: Kolkata Knights | D20: 2022 | E20: 9 | F20: 15 | G20: 1.67 | H20: 6 | I20: 1 - Poor Buy | J20: 200 | K20: 15.38 | L20: 117.65 | M20: 57 | N20: 10 | O20: 6.55 | P20: 0.71 | Q20: 42.86
A21: Sanjay Kumar | B21: Batsman | C21: Chennai Tigers | D21: 2022 | E21: 2.5 | F21: 0 | G21: 0 | H21: 8 | I21: 1 - Poor Buy | J21: 280 | K21: 23.33 | L21: 116.67 | M21: 48.57
A22: Deepak Nair | B22: Bowler | C22: Hyderabad Hawks | D22: 2023 | E22: 1.8 | F22: 100 | G22: 55.56 | H22: 1 | I22: 5 - Steal_Buy | N22: 26 | O22: 5.09 | P22: 1.86 | Q22: 61.78
A23: Priya Singh | B23: Bowler | C23: Kolkata Knights | D23: 2023 | E23: 2 | F23: 68 | G23: 34 | H23: 2 | I23: 5 - Steal_Buy | N23: 25 | O23: 5.69 | P23: 1.79 | Q23: 60.34
A24: Suresh Rao | B24: Bowler | C24: Chennai Tigers | D24: 2023 | E24: 2.5 | F24: 60 | G24: 24 | H24: 3 | I24: 5 - Steal_Buy | N24: 23 | O24: 5.63 | P24: 1.64 | Q24: 59.52
A25: Kiran Mehta | B25: Batsman | C25: Mumbai Lions | D25: 2023 | E25: 4 | F25: 50 | G25: 12.5 | H25: 4 | I25: 5 - Steal_Buy | J25: 390 | K25: 30 | L25: 125.81 | M25: 55.38
A26: Chris Blake | B26: Batsman | C26: Delhi Dynamos | D26: 2023 | E26: 9 | F26: 100 | G26: 11.11 | H26: 1 | I26: 5 - Steal_Buy | J26: 520 | K26: 43.33 | L26: 157.58 | M26: 76.92
A27: Tom Sullivan | B27: Batsman | C27: Rajasthan Riders | D27: 2023 | E27: 8 | F27: 82.9 | G27: 10.36 | H27: 2 | I27: 5 - Steal_Buy | J27: 430 | K27: 33.08 | L27: 126.47 | M27: 59.53
A28: Ankit Verma | B28: Batsman | C28: Kolkata Knights | D28: 2023 | E28: 3.5 | F28: 28.6 | G28: 8.17 | H28: 6 | I28: 5 - Steal_Buy | J28: 310 | K28: 25.83 | L28: 119.23 | M28: 51.61
A29: Vikram Das | B29: Batsman | C29: Hyderabad Hawks | D29: 2023 | E29: 6 | F29: 41.4 | G29: 6.9 | H29: 5 | I29: 4 - Good_Buy | J29: 360 | K29: 27.69 | L29: 124.14 | M29: 50
A30: Hamid Shaikh | B30: Batsman | C30: Delhi Dynamos | D30: 2023 | E30: 3.5 | F30: 22.9 | G30: 6.54 | H30: 7 | I30: 4 - Good_Buy | J30: 300 | K30: 25 | L30: 117.65 | M30: 50
A31: Nathan Ford | B31: Bowler | C31: Punjab Royals | D31: 2023 | E31: 7.5 | F31: 44 | G31: 5.87 | H31: 4 | I31: 3 - Fair_Buy | N31: 20 | O31: 5.38 | P31: 1.43 | Q31: 56.09
A32: Praveen Joshi | B32: Bowler | C32: Mumbai Lions | D32: 2023 | E32: 1.2 | F32: 6 | G32: 5 | H32: 6 | I32: 3 - Fair_Buy | N32: 17 | O32: 6.25 | P32: 1.21 | Q32: 49.68
A33: Luca Ferreira | B33: All-Rounder | C33: Delhi Dynamos | D33: 2023 | E33: 12 | F33: 60 | G33: 5 | H33: 3 | I33: 3 - Fair_Buy | J33: 290 | K33: 22.31 | L33: 126.09 | M33: 57.24 | N33: 13 | O33: 6.5 | P33: 0.93 | Q33: 42.67
A34: James Tanner | B34: All-Rounder | C34: Rajasthan Riders | D34: 2023 | E34: 13.5 | F34: 64 | G34: 4.74 | H34: 2 | I34: 3 - Fair_Buy | J34: 280 | K34: 20 | L34: 127.27 | M34: 55.71 | N34: 12 | O34: 6.46 | P34: 0.86 | Q34: 43.4
A35: Carlos Mendez | B35: All-Rounder | C35: Punjab Royals | D35: 2023 | E35: 10 | F35: 46 | G35: 4.6 | H35: 4 | I35: 3 - Fair_Buy | J35: 260 | K35: 20 | L35: 123.81 | M35: 56.92 | N35: 11 | O35: 6.41 | P35: 0.79 | Q35: 42.75
A36: Arjun Patel | B36: All-Rounder | C36: Chennai Tigers | D36: 2023 | E36: 17 | F36: 77 | G36: 4.53 | H36: 1 | I36: 3 - Fair_Buy | J36: 310 | K36: 22.14 | L36: 129.17 | M36: 63.23 | N36: 14 | O36: 6.73 | P36: 1 | Q36: 43.27
A37: Raj Sharma | B37: Batsman | C37: Mumbai Lions | D37: 2023 | E37: 16.5 | F37: 74.3 | G37: 4.5 | H37: 3 | I37: 3 - Fair_Buy | J37: 480 | K37: 34.29 | L37: 126.32 | M37: 57.5
A38: Rohan Gill | B38: All-Rounder | C38: Mumbai Lions | D38: 2023 | E38: 9.5 | F38: 33 | G38: 3.47 | H38: 5 | I38: 2 - Overpriced | J38: 240 | K38: 17.14 | L38: 120 | M38: 55.83 | N38: 11 | O38: 6.2 | P38: 0.79 | Q38: 40.58
A39: Brendon Chase | B39: Bowler | C39: Punjab Royals | D39: 2023 | E39: 6.5 | F39: 22 | G39: 3.38 | H39: 5 | I39: 2 - Overpriced | N39: 21 | O39: 5.92 | P39: 1.5 | Q39: 48.61
A40: Marco de Bruyn | B40: All-Rounder | C40: Kolkata Knights | D40: 2023 | E40: 11 | F40: 16 | G40: 1.45 | H40: 6 | I40: 1 - Poor Buy | J40: 200 | K40: 15.38 | L40: 117.65 | M40: 57 | N40: 10 | O40: 6.55 | P40: 0.71 | Q40: 42.86
...

Sheet Pivot Table 5

Sheet Batting
A1: player_name | B1: player_role | C1: team | D1: season | E1: runs | F1: average | G1: strike_rate | H1: bdry_pct
A2: Raj Sharma | B2: Batsman | C2: Mumbai Lions | D2: 2022 | E2: 480 | F2: 34.29 | G2: 126.32 | H2: 57.5
A3: Raj Sharma | B3: Batsman | C3: Mumbai Lions | D3: 2023 | E3: 520 | F3: 37.14 | G3: 130 | H3: 58.46
A4: Arjun Patel | B4: All-Rounder | C4: Chennai Tigers | D4: 2022 | E4: 310 | F4: 22.14 | G4: 129.17 | H4: 63.23
A5: Arjun Patel | B5: All-Rounder | C5: Chennai Tigers | D5: 2023 | E5: 340 | F5: 24.29 | G5: 130.77 | H5: 63.53
A6: Chris Blake | B6: Batsman | C6: Delhi Dynamos | D6: 2022 | E6: 520 | F6: 43.33 | G6: 157.58 | H6: 76.92
A7: Chris Blake | B7: Batsman | C7: Delhi Dynamos | D7: 2023 | E7: 610 | F7: 43.57 | G7: 164.86 | H7: 75.08
A8: Kiran Mehta | B8: Batsman | C8: Mumbai Lions | D8: 2022 | E8: 390 | F8: 30 | G8: 125.81 | H8: 55.38
A9: Kiran Mehta | B9: Batsman | C9: Mumbai Lions | D9: 2023 | E9: 420 | F9: 30 | G9: 127.27 | H9: 57.62
A10: James Tanner | B10: All-Rounder | C10: Rajasthan Riders | D10: 2022 | E10: 280 | F10: 20 | G10: 127.27 | H10: 55.71
A11: James Tanner | B11: All-Rounder | C11: Rajasthan Riders | D11: 2023 | E11: 310 | F11: 22.14 | G11: 131.91 | H11: 58.06
A12: Vikram Das | B12: Batsman | C12: Hyderabad Hawks | D12: 2022 | E12: 360 | F12: 27.69 | G12: 124.14 | H12: 50
A13: Vikram Das | B13: Batsman | C13: Hyderabad Hawks | D13: 2023 | E13: 400 | F13: 28.57 | G13: 129.03 | H13: 51
... A29: Carlos Mendez | B29: All-Rounder | C29: Punjab Royals | D29: 2023 | E29: 290 | F29: 20.71 | G29: 126.09 | H29: 59.31

Sheet Bowling
A1: player_name | B1: player_role | C1: team | D1: season | E1: matches | F1: wickets | G1: economy | H1: wkt_per_match | I1: dot_pct
A2: Deepak Nair | B2: Bowler | C2: Hyderabad Hawks | D2: 2023 | E2: 14 | F2: 26 | G2: 5.09 | H2: 1.86 | I2: 61.78
A3: Priya Singh | B3: Bowler | C3: Kolkata Knights | D3: 2023 | E3: 14 | F3: 25 | G3: 5.69 | H3: 1.79 | I3: 60.34
A4: Deepak Nair | B4: Bowler | C4: Hyderabad Hawks | D4: 2022 | E4: 14 | F4: 24 | G4: 5.09 | H4: 1.71 | I4: 59.52
A5: Suresh Rao | B5: Bowler | C5: Chennai Tigers | D5: 2023 | E5: 14 | F5: 23 | G5: 5.63 | H5: 1.64 | I5: 59.52
A6: Priya Singh | B6: Bowler | C6: Kolkata Knights | D6: 2022 | E6: 14 | F6: 22 | G6: 5.54 | H6: 1.57 | I6: 56.55
A7: Suresh Rao | B7: Bowler | C7: Chennai Tigers | D7: 2022 | E7: 14 | F7: 21 | G7: 5.46 | H7: 1.5 | I7: 57.1
A8: Brendon Chase | B8: Bowler | C8: Punjab Royals | D8: 2023 | E8: 14 | F8: 21 | G8: 5.92 | H8: 1.5 | I8: 48.61
A9: Nathan Ford | B9: Bowler | C9: Punjab Royals | D9: 2022 | E9: 14 | F9: 20 | G9: 5.38 | H9: 1.43 | I9: 56.09
A10: Brendon Chase | B10: Bowler | C10: Punjab Royals | D10: 2022 | E10: 14 | F10: 19 | G10: 5.86 | H10: 1.36 | I10: 45.98
A11: Nathan Ford | B11: Bowler | C11: Punjab Royals | D11: 2023 | E11: 14 | F11: 18 | G11: 5.46 | H11: 1.29 | I11: 50.93
A12: Praveen Joshi | B12: Bowler | C12: Mumbai Lions | D12: 2023 | E12: 14 | F12: 17 | G12: 6.25 | H12: 1.21 | I12: 49.68
A13: Praveen Joshi | B13: Bowler | C13: Mumbai Lions | D13: 2022 | E13: 14 | F13: 15 | G13: 6.2 | H13: 1.07 | I13: 46.67
... A25: Marco de Bruyn | B25: All-Rounder | C25: Kolkata Knights | D25: 2022 | E25: 13 | F25: 8 | G25: 6.84 | H25: 0.62 | I25: 41.67
